Workbook

Sheet nsiv.io
A1: NACA AIRFOIL
A2: NSIV.IO
A3: https://nsiv.io/
G5: M | H5: P | I5: XX
F6: 4 DIGIT = | G6: 2 | H6: 4 | I6: 12
G7: =G6/100 -> 0.02 | H7: =H6/10 -> 0.4 | I7: =I6/100 -> 0.12
A10: Camber / Cuerda | F10: Extrados | H10: Intrados
A11: Xc | B11: Yc | C11: dYc/dx | D11: Yt | E11: Theta | F11: Xu | G11: Yu | H11: Xl | I11: Yl
A12: 0 | B12: =IF(A12<$H$7,(($G$7/$H$7^2)*(2*$H$7*A12-A12^2)),(($G$7/(1-$H$7)^2)*(1-2*$H$7+2*$H$7*A12-A12^2))) -> 0 | C12: =IF(A12<$H$7,(2*$G$7/$H$7^2)*($H$7-A12),(2*$G$7/(1-$H$7)^2)*($H$7-A12)) -> 0.1 | D12: =($I$7/0.2)*(0.2969*A12^0.5-0.126*A12-0.3516*A12^2+0.2843*A12^3-0.1015*A12^4) -> 0 | E12: =ATAN(C12) -> 0.099668652 | F12: =A12-D12*SIN(E12) -> 0 | G12: =B12+D12*COS(E12) -> 0 | H12: =A12+D12*SIN(E12) -> 0 | I12: =B12-D12*COS(E12) -> 0
A13: 0.01 | B13: =IF(A13<$H$7,(($G$7/$H$7^2)*(2*$H$7*A13-A13^2)),(($G$7/(1-$H$7)^2)*(1-2*$H$7+2*$H$7*A13-A13^2))) -> 0.0009875 | C13: =IF(A13<$H$7,(2*$G$7/$H$7^2)*($H$7-A13),(2*$G$7/(1-$H$7)^2)*($H$7-A13)) -> 0.0975 | D13: =($I$7/0.2)*(0.2969*A13^0.5-0.126*A13-0.3516*A13^2+0.2843*A13^3-0.1015*A13^4) -> 0.017037074 | E13: =ATAN(C13) -> 0.097192797 | F13: =A13-D13*SIN(E13) -> 0.0083467249 | G13: =B13+D13*COS(E13) -> 0.017944167 | H13: =A13+D13*SIN(E13) -> 0.011653275 | I13: =B13-D13*COS(E13) -> -0.015969167
A14: 0.02 | B14: =IF(A14<$H$7,(($G$7/$H$7^2)*(2*$H$7*A14-A14^2)),(($G$7/(1-$H$7)^2)*(1-2*$H$7+2*$H$7*A14-A14^2))) -> 0.00195 | C14: =IF(A14<$H$7,(2*$G$7/$H$7^2)*($H$7-A14),(2*$G$7/(1-$H$7)^2)*($H$7-A14)) -> 0.095 | D14: =($I$7/0.2)*(0.2969*A14^0.5-0.126*A14-0.3516*A14^2+0.2843*A14^3-0.1015*A14^4) -> 0.023597771 | E14: =ATAN(C14) -> 0.094715746 | F14: =A14-D14*SIN(E14) -> 0.01776826 | G14: =B14+D14*COS(E14) -> 0.025442002 | H14: =A14+D14*SIN(E14) -> 0.02223174 | I14: =B14-D14*COS(E14) -> -0.021542002
A15: 0.03 | B15: =IF(A15<$H$7,(($G$7/$H$7^2)*(2*$H$7*A15-A15^2)),(($G$7/(1-$H$7)^2)*(1-2*$H$7+2*$H$7*A15-A15^2))) -> 0.0028875 | C15: =IF(A15<$H$7,(2*$G$7/$H$7^2)*($H$7-A15),(2*$G$7/(1-$H$7)^2)*($H$7-A15)) -> 0.0925 | D15: =($I$7/0.2)*(0.2969*A15^0.5-0.126*A15-0.3516*A15^2+0.2843*A15^3-0.1015*A15^4) -> 0.028401445 | E15: =ATAN(C15) -> 0.092237528 | F15: =A15-D15*SIN(E15) -> 0.027384034 | G15: =B15+D15*COS(E15) -> 0.031168215 | H15: =A15+D15*SIN(E15) -> 0.032615966 | I15: =B15-D15*COS(E15) -> -0.025393215
A16: 0.04 | B16: =IF(A16<$H$7,(($G$7/$H$7^2)*(2*$H$7*A16-A16^2)),(($G$7/(1-$H$7)^2)*(1-2*$H$7+2*$H$7*A16-A16^2))) -> 0.0038 | C16: =IF(A16<$H$7,(2*$G$7/$H$7^2)*($H$7-A16),(2*$G$7/(1-$H$7)^2)*($H$7-A16)) -> 0.09 | D16: =($I$7/0.2)*(0.2969*A16^0.5-0.126*A16-0.3516*A16^2+0.2843*A16^3-0.1015*A16^4) -> 0.032277225 | E16: =ATAN(C16) -> 0.089758174 | F16: =A16-D16*SIN(E16) -> 0.037106744 | G16: =B16+D16*COS(E16) -> 0.035947291 | H16: =A16+D16*SIN(E16) -> 0.042893256 | I16: =B16-D16*COS(E16) -> -0.028347291
A17: 0.05 | B17: =IF(A17<$H$7,(($G$7/$H$7^2)*(2*$H$7*A17-A17^2)),(($G$7/(1-$H$7)^2)*(1-2*$H$7+2*$H$7*A17-A17^2))) -> 0.0046875 | C17: =IF(A17<$H$7,(2*$G$7/$H$7^2)*($H$7-A17),(2*$G$7/(1-$H$7)^2)*($H$7-A17)) -> 0.0875 | D17: =($I$7/0.2)*(0.2969*A17^0.5-0.126*A17-0.3516*A17^2+0.2843*A17^3-0.1015*A17^4) -> 0.035546857 | E17: =ATAN(C17) -> 0.087277713 | F17: =A17-D17*SIN(E17) -> 0.046901489 | G17: =B17+D17*COS(E17) -> 0.040099055 | H17: =A17+D17*SIN(E17) -> 0.053098511 | I17: =B17-D17*COS(E17) -> -0.030724055
A18: 0.06 | B18: =IF(A18<$H$7,(($G$7/$H$7^2)*(2*$H$7*A18-A18^2)),(($G$7/(1-$H$7)^2)*(1-2*$H$7+2*$H$7*A18-A18^2))) -> 0.00555 | C18: =IF(A18<$H$7,(2*$G$7/$H$7^2)*($H$7-A18),(2*$G$7/(1-$H$7)^2)*($H$7-A18)) -> 0.085 | D18: =($I$7/0.2)*(0.2969*A18^0.5-0.126*A18-0.3516*A18^2+0.2843*A18^3-0.1015*A18^4) -> 0.03837581 | E18: =ATAN(C18) -> 0.084796175 | F18: =A18-D18*SIN(E18) -> 0.056749776 | G18: =B18+D18*COS(E18) -> 0.043787924 | H18: =A18+D18*SIN(E18) -> 0.063250224 | I18: =B18-D18*COS(E18) -> -0.032687924
A19: 0.07 | B19: =IF(A19<$H$7,(($G$7/$H$7^2)*(2*$H$7*A19-A19^2)),(($G$7/(1-$H$7)^2)*(1-2*$H$7+2*$H$7*A19-A19^2))) -> 0.0063875 | C19: =IF(A19<$H$7,(2*$G$7/$H$7^2)*($H$7-A19),(2*$G$7/(1-$H$7)^2)*($H$7-A19)) -> 0.0825 | D19: =($I$7/0.2)*(0.2969*A19^0.5-0.126*A19-0.3516*A19^2+0.2843*A19^3-0.1015*A19^4) -> 0.040862757 | E19: =ATAN(C19) -> 0.082313589 | F19: =A19-D19*SIN(E19) -> 0.066640237 | G19: =B19+D19*COS(E19) -> 0.047111901 | H19: =A19+D19*SIN(E19) -> 0.073359763 | I19: =B19-D19*COS(E19) -> -0.034336901
A20: 0.08 | B20: =IF(A20<$H$7,(($G$7/$H$7^2)*(2*$H$7*A20-A20^2)),(($G$7/(1-$H$7)^2)*(1-2*$H$7+2*$H$7*A20-A20^2))) -> 0.0072 | C20: =IF(A20<$H$7,(2*$G$7/$H$7^2)*($H$7-A20),(2*$G$7/(1-$H$7)^2)*($H$7-A20)) -> 0.08 | D20: =($I$7/0.2)*(0.2969*A20^0.5-0.126*A20-0.3516*A20^2+0.2843*A20^3-0.1015*A20^4) -> 0.043072299 | E20: =ATAN(C20) -> 0.079829986 | F20: =A20-D20*SIN(E20) -> 0.07656519 | G20: =B20+D20*COS(E20) -> 0.050135126 | H20: =A20+D20*SIN(E20) -> 0.08343481 | I20: =B20-D20*COS(E20) -> -0.035735126
A21: 0.09 | B21: =IF(A21<$H$7,(($G$7/$H$7^2)*(2*$H$7*A21-A21^2)),(($G$7/(1-$H$7)^2)*(1-2*$H$7+2*$H$7*A21-A21^2))) -> 0.0079875 | C21: =IF(A21<$H$7,(2*$G$7/$H$7^2)*($H$7-A21),(2*$G$7/(1-$H$7)^2)*($H$7-A21)) -> 0.0775 | D21: =($I$7/0.2)*(0.2969*A21^0.5-0.126*A21-0.3516*A21^2+0.2843*A21^3-0.1015*A21^4) -> 0.045049581 | E21: =ATAN(C21) -> 0.077345395 | F21: =A21-D21*SIN(E21) -> 0.086519095 | G21: =B21+D21*COS(E21) -> 0.052902398 | H21: =A21+D21*SIN(E21) -> 0.093480905 | I21: =B21-D21*COS(E21) -> -0.036927398
A22: 0.1 | B22: =IF(A22<$H$7,(($G$7/$H$7^2)*(2*$H$7*A22-A22^2)),(($G$7/(1-$H$7)^2)*(1-2*$H$7+2*$H$7*A22-A22^2))) -> 0.00875 | C22: =IF(A22<$H$7,(2*$G$7/$H$7^2)*($H$7-A22),(2*$G$7/(1-$H$7)^2)*($H$7-A22)) -> 0.075 | D22: =($I$7/0.2)*(0.2969*A22^0.5-0.126*A22-0.3516*A22^2+0.2843*A22^3-0.1015*A22^4) -> 0.046827704 | E22: =ATAN(C22) -> 0.074859848 | F22: =A22-D22*SIN(E22) -> 0.096497758 | G22: =B22+D22*COS(E22) -> 0.055446554 | H22: =A22+D22*SIN(E22) -> 0.10350224 | I22: =B22-D22*COS(E22) -> -0.037946554
A23: 0.11 | B23: =IF(A23<$H$7,(($G$7/$H$7^2)*(2*$H$7*A23-A23^2)),(($G$7/(1-$H$7)^2)*(1-2*$H$7+2*$H$7*A23-A23^2))) -> 0.0094875 | C23: =IF(A23<$H$7,(2*$G$7/$H$7^2)*($H$7-A23),(2*$G$7/(1-$H$7)^2)*($H$7-A23)) -> 0.0725 | D23: =($I$7/0.2)*(0.2969*A23^0.5-0.126*A23-0.3516*A23^2+0.2843*A23^3-0.1015*A23^4) -> 0.048431864 | E23: =ATAN(C23) -> 0.072373373 | F23: =A23-D23*SIN(E23) -> 0.10649788 | G23: =B23+D23*COS(E23) -> 0.057792578 | H23: =A23+D23*SIN(E23) -> 0.11350212 | I23: =B23-D23*COS(E23) -> -0.038817578
... A112: 1 | B112: =IF(A112<$H$7,(($G$7/$H$7^2)*(2*$H$7*A112-A112^2)),(($G$7/(1-$H$7)^2)*(1-2*$H$7+2*$H$7*A112-A112^2))) -> 0 | C112: =IF(A112<$H$7,(2*$G$7/$H$7^2)*($H$7-A112),(2*$G$7/(1-$H$7)^2)*($H$7-A112)) -> -0.066666667 | D112: =($I$7/0.2)*(0.2969*A112^0.5-0.126*A112-0.3516*A112^2+0.2843*A112^3-0.1015*A112^4) -> 0.00126 | E112: =ATAN(C112) -> -0.066568164 | F112: =A112-D112*SIN(E112) -> 1.0000838 | G112: =B112+D112*COS(E112) -> 0.0012572093 | H112: =A112+D112*SIN(E112) -> 0.99991619 | I112: =B112-D112*COS(E112) -> -0.0012572093

Sheet Points
A1: #Group | B1: Point | C1: X_cord | D1: Y_cord | E1: Z_cord
A2: 1 | B2: 1 | C2: =nsiv.io!F112 -> 1.0000838 | D2: =nsiv.io!G112 -> 0.0012572093 | E2: 0
A3: 1 | B3: 2 | C3: =nsiv.io!F111 -> 0.99017364 | D3: =nsiv.io!G111 -> 0.003309898 | E3: 0
A4: 1 | B4: 3 | C4: =nsiv.io!F110 -> 0.9802593 | D4: =nsiv.io!G110 -> 0.0053346938 | E4: 0
A5: 1 | B5: 4 | C5: =nsiv.io!F109 -> 0.97034086 | D5: =nsiv.io!G109 -> 0.0073319341 | E5: 0
A6: 1 | B6: 5 | C6: =nsiv.io!F108 -> 0.96041839 | D6: =nsiv.io!G108 -> 0.0093019402 | E6: 0
A7: 1 | B7: 6 | C7: =nsiv.io!F107 -> 0.95049198 | D7: =nsiv.io!G107 -> 0.011245017 | E7: 0
A8: 1 | B8: 7 | C8: =nsiv.io!F106 -> 0.94056169 | D8: =nsiv.io!G106 -> 0.013161454 | E8: 0
A9: 1 | B9: 8 | C9: =nsiv.io!F105 -> 0.93062758 | D9: =nsiv.io!G105 -> 0.015051522 | E9: 0
A10: 1 | B10: 9 | C10: =nsiv.io!F104 -> 0.92068973 | D10: =nsiv.io!G104 -> 0.016915478 | E10: 0
A11: 1 | B11: 10 | C11: =nsiv.io!F103 -> 0.9107482 | D11: =nsiv.io!G103 -> 0.018753561 | E11: 0
A12: 1 | B12: 11 | C12: =nsiv.io!F102 -> 0.90080305 | D12: =nsiv.io!G102 -> 0.020565994 | E12: 0
A13: 1 | B13: 12 | C13: =nsiv.io!F101 -> 0.89085434 | D13: =nsiv.io!G101 -> 0.022352983 | E13: 0
A14: 1 | B14: 13 | C14: =nsiv.io!F100 -> 0.88090212 | D14: =nsiv.io!G100 -> 0.024114716 | E14: 0
A15: 1 | B15: 14 | C15: =nsiv.io!F99 -> 0.87094645 | D15: =nsiv.io!G99 -> 0.025851365 | E15: 0
A16: 1 | B16: 15 | C16: =nsiv.io!F98 -> 0.8609874 | D16: =nsiv.io!G98 -> 0.027563087 | E16: 0
A17: 1 | B17: 16 | C17: =nsiv.io!F97 -> 0.851025 | D17: =nsiv.io!G97 -> 0.029250018 | E17: 0
A18: 1 | B18: 17 | C18: =nsiv.io!F96 -> 0.84105932 | D18: =nsiv.io!G96 -> 0.030912279 | E18: 0
A19: 1 | B19: 18 | C19: =nsiv.io!F95 -> 0.83109039 | D19: =nsiv.io!G95 -> 0.032549973 | E19: 0
A20: 1 | B20: 19 | C20: =nsiv.io!F94 -> 0.82111828 | D20: =nsiv.io!G94 -> 0.034163186 | E20: 0
A21: 1 | B21: 20 | C21: =nsiv.io!F93 -> 0.81114303 | D21: =nsiv.io!G93 -> 0.035751986 | E21: 0
A22: 1 | B22: 21 | C22: =nsiv.io!F92 -> 0.80116468 | D22: =nsiv.io!G92 -> 0.037316422 | E22: 0
A23: 1 | B23: 22 | C23: =nsiv.io!F91 -> 0.79118328 | D23: =nsiv.io!G91 -> 0.038856527 | E23: 0
A24: 1 | B24: 23 | C24: =nsiv.io!F90 -> 0.78119888 | D24: =nsiv.io!G90 -> 0.040372314 | E24: 0
A25: 1 | B25: 24 | C25: =nsiv.io!F89 -> 0.77121152 | D25: =nsiv.io!G89 -> 0.04186378 | E25: 0
A26: 1 | B26: 25 | C26: =nsiv.io!F88 -> 0.76122124 | D26: =nsiv.io!G88 -> 0.043330901 | E26: 0
A27: 1 | B27: 26 | C27: =nsiv.io!F87 -> 0.75122808 | D27: =nsiv.io!G87 -> 0.044773636 | E27: 0
A28: 1 | B28: 27 | C28: =nsiv.io!F86 -> 0.74123209 | D28: =nsiv.io!G86 -> 0.046191925 | E28: 0
A29: 1 | B29: 28 | C29: =nsiv.io!F85 -> 0.73123331 | D29: =nsiv.io!G85 -> 0.047585687 | E29: 0
A30: 1 | B30: 29 | C30: =nsiv.io!F84 -> 0.72123178 | D30: =nsiv.io!G84 -> 0.048954824 | E30: 0
A31: 1 | B31: 30 | C31: =nsiv.io!F83 -> 0.71122753 | D31: =nsiv.io!G83 -> 0.050299217 | E31: 0
A32: 1 | B32: 31 | C32: =nsiv.io!F82 -> 0.70122062 | D32: =nsiv.io!G82 -> 0.051618729 | E32: 0
A33: 1 | B33: 32 | C33: =nsiv.io!F81 -> 0.69121109 | D33: =nsiv.io!G81 -> 0.052913201 | E33: 0
A34: 1 | B34: 33 | C34: =nsiv.io!F80 -> 0.68119896 | D34: =nsiv.io!G80 -> 0.054182454 | E34: 0
A35: 1 | B35: 34 | C35: =nsiv.io!F79 -> 0.67118429 | D35: =nsiv.io!G79 -> 0.05542629 | E35: 0
A36: 1 | B36: 35 | C36: =nsiv.io!F78 -> 0.66116711 | D36: =nsiv.io!G78 -> 0.056644487 | E36: 0
A37: 1 | B37: 36 | C37: =nsiv.io!F77 -> 0.65114747 | D37: =nsiv.io!G77 -> 0.057836805 | E37: 0
A38: 1 | B38: 37 | C38: =nsiv.io!F76 -> 0.64112541 | D38: =nsiv.io!G76 -> 0.05900298 | E38: 0
A39: 1 | B39: 38 | C39: =nsiv.io!F75 -> 0.63110097 | D39: =nsiv.io!G75 -> 0.060142727 | E39: 0
A40: 1 | B40: 39 | C40: =nsiv.io!F74 -> 0.6210742 | D40: =nsiv.io!G74 -> 0.061255738 | E40: 0
...
